[2024-01-13T21:08:39.913+0000] {taskinstance.py:1957} INFO - Dependencies all met for dep_context=non-requeueable deps ti=<TaskInstance: data_ingestion_gcs_dag.local_to_gcs_task scheduled__2024-01-12T00:00:00+00:00 [queued]>
[2024-01-13T21:08:39.925+0000] {taskinstance.py:1957} INFO - Dependencies all met for dep_context=requeueable deps ti=<TaskInstance: data_ingestion_gcs_dag.local_to_gcs_task scheduled__2024-01-12T00:00:00+00:00 [queued]>
[2024-01-13T21:08:39.929+0000] {taskinstance.py:2171} INFO - Starting attempt 1 of 2
[2024-01-13T21:08:39.949+0000] {taskinstance.py:2192} INFO - Executing <Task(PythonOperator): local_to_gcs_task> on 2024-01-12 00:00:00+00:00
[2024-01-13T21:08:39.956+0000] {standard_task_runner.py:60} INFO - Started process 288 to run task
[2024-01-13T21:08:39.964+0000] {standard_task_runner.py:87} INFO - Running: ['***', 'tasks', 'run', 'data_ingestion_gcs_dag', 'local_to_gcs_task', 'scheduled__2024-01-12T00:00:00+00:00', '--job-id', '4', '--raw', '--subdir', 'DAGS_FOLDER/data_ingestion_gcs_dag.py', '--cfg-path', '/tmp/tmpeg219_8d']
[2024-01-13T21:08:39.970+0000] {standard_task_runner.py:88} INFO - Job 4: Subtask local_to_gcs_task
[2024-01-13T21:08:39.990+0000] {logging_mixin.py:188} WARNING - /home/***/.local/lib/python3.8/site-packages/***/settings.py:195 DeprecationWarning: The sql_alchemy_conn option in [core] has been moved to the sql_alchemy_conn option in [database] - the old setting has been used, but please update your config.
[2024-01-13T21:08:40.032+0000] {task_command.py:423} INFO - Running <TaskInstance: data_ingestion_gcs_dag.local_to_gcs_task scheduled__2024-01-12T00:00:00+00:00 [running]> on host c42f59e5a753
[2024-01-13T21:08:40.096+0000] {taskinstance.py:2481} INFO - Exporting env vars: AIRFLOW_CTX_DAG_OWNER='***' AIRFLOW_CTX_DAG_ID='data_ingestion_gcs_dag' AIRFLOW_CTX_TASK_ID='local_to_gcs_task' AIRFLOW_CTX_EXECUTION_DATE='2024-01-12T00:00:00+00:00' AIRFLOW_CTX_TRY_NUMBER='1' AIRFLOW_CTX_DAG_RUN_ID='scheduled__2024-01-12T00:00:00+00:00'
[2024-01-13T21:08:40.100+0000] {taskinstance.py:2699} ERROR - Task failed with exception
Traceback (most recent call last):
  File "/home/airflow/.local/lib/python3.8/site-packages/airflow/models/taskinstance.py", line 433, in _execute_task
    result = execute_callable(context=context, **execute_callable_kwargs)
  File "/home/airflow/.local/lib/python3.8/site-packages/airflow/operators/python.py", line 199, in execute
    return_value = self.execute_callable()
  File "/home/airflow/.local/lib/python3.8/site-packages/airflow/operators/python.py", line 216, in execute_callable
    return self.python_callable(*self.op_args, **self.op_kwargs)
  File "/opt/airflow/dags/data_ingestion_gcs_dag.py", line 70, in upload_to_gcs
    client = storage.Client()
  File "/home/airflow/.local/lib/python3.8/site-packages/google/cloud/storage/client.py", line 172, in __init__
    super(Client, self).__init__(
  File "/home/airflow/.local/lib/python3.8/site-packages/google/cloud/client/__init__.py", line 320, in __init__
    _ClientProjectMixin.__init__(self, project=project, credentials=credentials)
  File "/home/airflow/.local/lib/python3.8/site-packages/google/cloud/client/__init__.py", line 268, in __init__
    project = self._determine_default(project)
  File "/home/airflow/.local/lib/python3.8/site-packages/google/cloud/client/__init__.py", line 287, in _determine_default
    return _determine_default_project(project)
  File "/home/airflow/.local/lib/python3.8/site-packages/google/cloud/_helpers/__init__.py", line 152, in _determine_default_project
    _, project = google.auth.default()
  File "/home/airflow/.local/lib/python3.8/site-packages/google/auth/_default.py", line 657, in default
    credentials, project_id = checker()
  File "/home/airflow/.local/lib/python3.8/site-packages/google/auth/_default.py", line 650, in <lambda>
    lambda: _get_explicit_environ_credentials(quota_project_id=quota_project_id),
  File "/home/airflow/.local/lib/python3.8/site-packages/google/auth/_default.py", line 270, in _get_explicit_environ_credentials
    credentials, project_id = load_credentials_from_file(
  File "/home/airflow/.local/lib/python3.8/site-packages/google/auth/_default.py", line 114, in load_credentials_from_file
    raise exceptions.DefaultCredentialsError(
google.auth.exceptions.DefaultCredentialsError: File ~/.google/credentials/google_credentials.json was not found.
[2024-01-13T21:08:40.114+0000] {taskinstance.py:1138} INFO - Marking task as UP_FOR_RETRY. dag_id=data_ingestion_gcs_dag, task_id=local_to_gcs_task, execution_date=20240112T000000, start_date=20240113T210839, end_date=20240113T210840
[2024-01-13T21:08:40.146+0000] {standard_task_runner.py:107} ERROR - Failed to execute job 4 for task local_to_gcs_task (File ~/.google/credentials/google_credentials.json was not found.; 288)
[2024-01-13T21:08:40.179+0000] {local_task_job_runner.py:234} INFO - Task exited with return code 1
[2024-01-13T21:08:40.199+0000] {taskinstance.py:3281} INFO - 0 downstream tasks scheduled from follow-on schedule check
