[2024-01-13T21:23:02.909+0000] {taskinstance.py:1957} INFO - Dependencies all met for dep_context=non-requeueable deps ti=<TaskInstance: data_ingestion_gcs_dag.local_to_gcs_task manual__2024-01-13T21:08:30.060253+00:00 [queued]>
[2024-01-13T21:23:02.916+0000] {taskinstance.py:1957} INFO - Dependencies all met for dep_context=requeueable deps ti=<TaskInstance: data_ingestion_gcs_dag.local_to_gcs_task manual__2024-01-13T21:08:30.060253+00:00 [queued]>
[2024-01-13T21:23:02.918+0000] {taskinstance.py:2171} INFO - Starting attempt 2 of 2
[2024-01-13T21:23:02.931+0000] {taskinstance.py:2192} INFO - Executing <Task(PythonOperator): local_to_gcs_task> on 2024-01-13 21:08:30.060253+00:00
[2024-01-13T21:23:02.941+0000] {standard_task_runner.py:60} INFO - Started process 176 to run task
[2024-01-13T21:23:02.945+0000] {standard_task_runner.py:87} INFO - Running: ['***', 'tasks', 'run', 'data_ingestion_gcs_dag', 'local_to_gcs_task', 'manual__2024-01-13T21:08:30.060253+00:00', '--job-id', '10', '--raw', '--subdir', 'DAGS_FOLDER/data_ingestion_gcs_dag.py', '--cfg-path', '/tmp/tmpr2nxy795']
[2024-01-13T21:23:02.952+0000] {standard_task_runner.py:88} INFO - Job 10: Subtask local_to_gcs_task
[2024-01-13T21:23:02.972+0000] {logging_mixin.py:188} WARNING - /home/***/.local/lib/python3.8/site-packages/***/settings.py:195 DeprecationWarning: The sql_alchemy_conn option in [core] has been moved to the sql_alchemy_conn option in [database] - the old setting has been used, but please update your config.
[2024-01-13T21:23:03.017+0000] {task_command.py:423} INFO - Running <TaskInstance: data_ingestion_gcs_dag.local_to_gcs_task manual__2024-01-13T21:08:30.060253+00:00 [running]> on host 6bca031b1185
[2024-01-13T21:23:03.111+0000] {taskinstance.py:2481} INFO - Exporting env vars: AIRFLOW_CTX_DAG_OWNER='***' AIRFLOW_CTX_DAG_ID='data_ingestion_gcs_dag' AIRFLOW_CTX_TASK_ID='local_to_gcs_task' AIRFLOW_CTX_EXECUTION_DATE='2024-01-13T21:08:30.060253+00:00' AIRFLOW_CTX_TRY_NUMBER='2' AIRFLOW_CTX_DAG_RUN_ID='manual__2024-01-13T21:08:30.060253+00:00'
[2024-01-13T21:23:03.214+0000] {taskinstance.py:2699} ERROR - Task failed with exception
Traceback (most recent call last):
  File "/home/airflow/.local/lib/python3.8/site-packages/airflow/models/taskinstance.py", line 433, in _execute_task
    result = execute_callable(context=context, **execute_callable_kwargs)
  File "/home/airflow/.local/lib/python3.8/site-packages/airflow/operators/python.py", line 199, in execute
    return_value = self.execute_callable()
  File "/home/airflow/.local/lib/python3.8/site-packages/airflow/operators/python.py", line 216, in execute_callable
    return self.python_callable(*self.op_args, **self.op_kwargs)
  File "/opt/airflow/dags/data_ingestion_gcs_dag.py", line 74, in upload_to_gcs
    blob.upload_from_filename(local_file)
  File "/home/airflow/.local/lib/python3.8/site-packages/google/cloud/storage/blob.py", line 2929, in upload_from_filename
    self._handle_filename_and_upload(
  File "/home/airflow/.local/lib/python3.8/site-packages/google/cloud/storage/blob.py", line 2797, in _handle_filename_and_upload
    with open(filename, "rb") as file_obj:
FileNotFoundError: [Errno 2] No such file or directory: '/opt/airflow/yellow_tripdata_2021-01.parquet.gz'
[2024-01-13T21:23:03.226+0000] {taskinstance.py:1138} INFO - Marking task as FAILED. dag_id=data_ingestion_gcs_dag, task_id=local_to_gcs_task, execution_date=20240113T210830, start_date=20240113T212302, end_date=20240113T212303
[2024-01-13T21:23:03.247+0000] {standard_task_runner.py:107} ERROR - Failed to execute job 10 for task local_to_gcs_task ([Errno 2] No such file or directory: '/opt/airflow/yellow_tripdata_2021-01.parquet.gz'; 176)
[2024-01-13T21:23:03.290+0000] {local_task_job_runner.py:234} INFO - Task exited with return code 1
[2024-01-13T21:23:03.307+0000] {taskinstance.py:3281} INFO - 0 downstream tasks scheduled from follow-on schedule check
